Traceback (most recent call last):
  File "/Users/air/ea_assistant/gmail_ingest.py", line 66, in <module>
    main()
  File "/Users/air/ea_assistant/gmail_ingest.py", line 42, in main
    results = service.users().messages().list(userId='me', labelIds=['INBOX'], maxResults=25).execute()
  File "/Users/air/Library/Python/3.9/lib/python/site-packages/googleapiclient/_helpers.py", line 130, in positional_wrapper
    return wrapped(*args, **kwargs)
  File "/Users/air/Library/Python/3.9/lib/python/site-packages/googleapiclient/http.py", line 923, in execute
    resp, content = _retry_request(
  File "/Users/air/Library/Python/3.9/lib/python/site-packages/googleapiclient/http.py", line 191, in _retry_request
    resp, content = http.request(uri, method, *args, **kwargs)
  File "/Users/air/Library/Python/3.9/lib/python/site-packages/google_auth_httplib2.py", line 209, in request
    self.credentials.before_request(self._request, method, uri, request_headers)
  File "/Users/air/Library/Python/3.9/lib/python/site-packages/google/auth/credentials.py", line 239, in before_request
    self._blocking_refresh(request)
  File "/Users/air/Library/Python/3.9/lib/python/site-packages/google/auth/credentials.py", line 202, in _blocking_refresh
    self.refresh(request)
  File "/Users/air/Library/Python/3.9/lib/python/site-packages/google/oauth2/credentials.py", line 409, in refresh
    ) = reauth.refresh_grant(
  File "/Users/air/Library/Python/3.9/lib/python/site-packages/google/oauth2/reauth.py", line 366, in refresh_grant
    _client._handle_error_response(response_data, retryable_error)
  File "/Users/air/Library/Python/3.9/lib/python/site-packages/google/oauth2/_client.py", line 69, in _handle_error_response
    raise exceptions.RefreshError(
google.auth.exceptions.RefreshError: ('invalid_scope: Bad Request', {'error': 'invalid_scope', 'error_description': 'Bad Request'})
Traceback (most recent call last):
  File "/Users/air/ea_assistant/gmail_ingest.py", line 66, in <module>
    main()
  File "/Users/air/ea_assistant/gmail_ingest.py", line 42, in main
    results = service.users().messages().list(userId='me', labelIds=['INBOX'], maxResults=25).execute()
  File "/Users/air/Library/Python/3.9/lib/python/site-packages/googleapiclient/_helpers.py", line 130, in positional_wrapper
    return wrapped(*args, **kwargs)
  File "/Users/air/Library/Python/3.9/lib/python/site-packages/googleapiclient/http.py", line 923, in execute
    resp, content = _retry_request(
  File "/Users/air/Library/Python/3.9/lib/python/site-packages/googleapiclient/http.py", line 191, in _retry_request
    resp, content = http.request(uri, method, *args, **kwargs)
  File "/Users/air/Library/Python/3.9/lib/python/site-packages/google_auth_httplib2.py", line 209, in request
    self.credentials.before_request(self._request, method, uri, request_headers)
  File "/Users/air/Library/Python/3.9/lib/python/site-packages/google/auth/credentials.py", line 239, in before_request
    self._blocking_refresh(request)
  File "/Users/air/Library/Python/3.9/lib/python/site-packages/google/auth/credentials.py", line 202, in _blocking_refresh
    self.refresh(request)
  File "/Users/air/Library/Python/3.9/lib/python/site-packages/google/oauth2/credentials.py", line 409, in refresh
    ) = reauth.refresh_grant(
  File "/Users/air/Library/Python/3.9/lib/python/site-packages/google/oauth2/reauth.py", line 366, in refresh_grant
    _client._handle_error_response(response_data, retryable_error)
  File "/Users/air/Library/Python/3.9/lib/python/site-packages/google/oauth2/_client.py", line 69, in _handle_error_response
    raise exceptions.RefreshError(
google.auth.exceptions.RefreshError: ('invalid_scope: Bad Request', {'error': 'invalid_scope', 'error_description': 'Bad Request'})
Traceback (most recent call last):
  File "/Users/air/ea_assistant/gmail_ingest.py", line 66, in <module>
    main()
  File "/Users/air/ea_assistant/gmail_ingest.py", line 42, in main
    results = service.users().messages().list(userId='me', labelIds=['INBOX'], maxResults=25).execute()
  File "/Users/air/Library/Python/3.9/lib/python/site-packages/googleapiclient/_helpers.py", line 130, in positional_wrapper
    return wrapped(*args, **kwargs)
  File "/Users/air/Library/Python/3.9/lib/python/site-packages/googleapiclient/http.py", line 923, in execute
    resp, content = _retry_request(
  File "/Users/air/Library/Python/3.9/lib/python/site-packages/googleapiclient/http.py", line 191, in _retry_request
    resp, content = http.request(uri, method, *args, **kwargs)
  File "/Users/air/Library/Python/3.9/lib/python/site-packages/google_auth_httplib2.py", line 209, in request
    self.credentials.before_request(self._request, method, uri, request_headers)
  File "/Users/air/Library/Python/3.9/lib/python/site-packages/google/auth/credentials.py", line 239, in before_request
    self._blocking_refresh(request)
  File "/Users/air/Library/Python/3.9/lib/python/site-packages/google/auth/credentials.py", line 202, in _blocking_refresh
    self.refresh(request)
  File "/Users/air/Library/Python/3.9/lib/python/site-packages/google/oauth2/credentials.py", line 409, in refresh
    ) = reauth.refresh_grant(
  File "/Users/air/Library/Python/3.9/lib/python/site-packages/google/oauth2/reauth.py", line 366, in refresh_grant
    _client._handle_error_response(response_data, retryable_error)
  File "/Users/air/Library/Python/3.9/lib/python/site-packages/google/oauth2/_client.py", line 69, in _handle_error_response
    raise exceptions.RefreshError(
google.auth.exceptions.RefreshError: ('invalid_scope: Bad Request', {'error': 'invalid_scope', 'error_description': 'Bad Request'})
Traceback (most recent call last):
  File "/Users/air/ea_assistant/gmail_ingest.py", line 66, in <module>
    main()
  File "/Users/air/ea_assistant/gmail_ingest.py", line 42, in main
    results = service.users().messages().list(userId='me', labelIds=['INBOX'], maxResults=25).execute()
  File "/Users/air/Library/Python/3.9/lib/python/site-packages/googleapiclient/_helpers.py", line 130, in positional_wrapper
    return wrapped(*args, **kwargs)
  File "/Users/air/Library/Python/3.9/lib/python/site-packages/googleapiclient/http.py", line 923, in execute
    resp, content = _retry_request(
  File "/Users/air/Library/Python/3.9/lib/python/site-packages/googleapiclient/http.py", line 191, in _retry_request
    resp, content = http.request(uri, method, *args, **kwargs)
  File "/Users/air/Library/Python/3.9/lib/python/site-packages/google_auth_httplib2.py", line 209, in request
    self.credentials.before_request(self._request, method, uri, request_headers)
  File "/Users/air/Library/Python/3.9/lib/python/site-packages/google/auth/credentials.py", line 239, in before_request
    self._blocking_refresh(request)
  File "/Users/air/Library/Python/3.9/lib/python/site-packages/google/auth/credentials.py", line 202, in _blocking_refresh
    self.refresh(request)
  File "/Users/air/Library/Python/3.9/lib/python/site-packages/google/oauth2/credentials.py", line 409, in refresh
    ) = reauth.refresh_grant(
  File "/Users/air/Library/Python/3.9/lib/python/site-packages/google/oauth2/reauth.py", line 366, in refresh_grant
    _client._handle_error_response(response_data, retryable_error)
  File "/Users/air/Library/Python/3.9/lib/python/site-packages/google/oauth2/_client.py", line 69, in _handle_error_response
    raise exceptions.RefreshError(
google.auth.exceptions.RefreshError: ('invalid_scope: Bad Request', {'error': 'invalid_scope', 'error_description': 'Bad Request'})
Traceback (most recent call last):
  File "/Users/air/ea_assistant/gmail_ingest.py", line 66, in <module>
    main()
  File "/Users/air/ea_assistant/gmail_ingest.py", line 42, in main
    results = service.users().messages().list(userId='me', labelIds=['INBOX'], maxResults=25).execute()
  File "/Users/air/Library/Python/3.9/lib/python/site-packages/googleapiclient/_helpers.py", line 130, in positional_wrapper
    return wrapped(*args, **kwargs)
  File "/Users/air/Library/Python/3.9/lib/python/site-packages/googleapiclient/http.py", line 923, in execute
    resp, content = _retry_request(
  File "/Users/air/Library/Python/3.9/lib/python/site-packages/googleapiclient/http.py", line 191, in _retry_request
    resp, content = http.request(uri, method, *args, **kwargs)
  File "/Users/air/Library/Python/3.9/lib/python/site-packages/google_auth_httplib2.py", line 209, in request
    self.credentials.before_request(self._request, method, uri, request_headers)
  File "/Users/air/Library/Python/3.9/lib/python/site-packages/google/auth/credentials.py", line 239, in before_request
    self._blocking_refresh(request)
  File "/Users/air/Library/Python/3.9/lib/python/site-packages/google/auth/credentials.py", line 202, in _blocking_refresh
    self.refresh(request)
  File "/Users/air/Library/Python/3.9/lib/python/site-packages/google/oauth2/credentials.py", line 409, in refresh
    ) = reauth.refresh_grant(
  File "/Users/air/Library/Python/3.9/lib/python/site-packages/google/oauth2/reauth.py", line 366, in refresh_grant
    _client._handle_error_response(response_data, retryable_error)
  File "/Users/air/Library/Python/3.9/lib/python/site-packages/google/oauth2/_client.py", line 69, in _handle_error_response
    raise exceptions.RefreshError(
google.auth.exceptions.RefreshError: ('invalid_scope: Bad Request', {'error': 'invalid_scope', 'error_description': 'Bad Request'})
Traceback (most recent call last):
  File "/Users/air/ea_assistant/gmail_ingest.py", line 66, in <module>
    main()
  File "/Users/air/ea_assistant/gmail_ingest.py", line 42, in main
    results = service.users().messages().list(userId='me', labelIds=['INBOX'], maxResults=25).execute()
  File "/Users/air/Library/Python/3.9/lib/python/site-packages/googleapiclient/_helpers.py", line 130, in positional_wrapper
    return wrapped(*args, **kwargs)
  File "/Users/air/Library/Python/3.9/lib/python/site-packages/googleapiclient/http.py", line 923, in execute
    resp, content = _retry_request(
  File "/Users/air/Library/Python/3.9/lib/python/site-packages/googleapiclient/http.py", line 191, in _retry_request
    resp, content = http.request(uri, method, *args, **kwargs)
  File "/Users/air/Library/Python/3.9/lib/python/site-packages/google_auth_httplib2.py", line 209, in request
    self.credentials.before_request(self._request, method, uri, request_headers)
  File "/Users/air/Library/Python/3.9/lib/python/site-packages/google/auth/credentials.py", line 239, in before_request
    self._blocking_refresh(request)
  File "/Users/air/Library/Python/3.9/lib/python/site-packages/google/auth/credentials.py", line 202, in _blocking_refresh
    self.refresh(request)
  File "/Users/air/Library/Python/3.9/lib/python/site-packages/google/oauth2/credentials.py", line 409, in refresh
    ) = reauth.refresh_grant(
  File "/Users/air/Library/Python/3.9/lib/python/site-packages/google/oauth2/reauth.py", line 366, in refresh_grant
    _client._handle_error_response(response_data, retryable_error)
  File "/Users/air/Library/Python/3.9/lib/python/site-packages/google/oauth2/_client.py", line 69, in _handle_error_response
    raise exceptions.RefreshError(
google.auth.exceptions.RefreshError: ('invalid_scope: Bad Request', {'error': 'invalid_scope', 'error_description': 'Bad Request'})
Traceback (most recent call last):
  File "/Users/air/ea_assistant/gmail_ingest.py", line 66, in <module>
    main()
  File "/Users/air/ea_assistant/gmail_ingest.py", line 42, in main
    results = service.users().messages().list(userId='me', labelIds=['INBOX'], maxResults=25).execute()
  File "/Users/air/Library/Python/3.9/lib/python/site-packages/googleapiclient/_helpers.py", line 130, in positional_wrapper
    return wrapped(*args, **kwargs)
  File "/Users/air/Library/Python/3.9/lib/python/site-packages/googleapiclient/http.py", line 923, in execute
    resp, content = _retry_request(
  File "/Users/air/Library/Python/3.9/lib/python/site-packages/googleapiclient/http.py", line 191, in _retry_request
    resp, content = http.request(uri, method, *args, **kwargs)
  File "/Users/air/Library/Python/3.9/lib/python/site-packages/google_auth_httplib2.py", line 209, in request
    self.credentials.before_request(self._request, method, uri, request_headers)
  File "/Users/air/Library/Python/3.9/lib/python/site-packages/google/auth/credentials.py", line 239, in before_request
    self._blocking_refresh(request)
  File "/Users/air/Library/Python/3.9/lib/python/site-packages/google/auth/credentials.py", line 202, in _blocking_refresh
    self.refresh(request)
  File "/Users/air/Library/Python/3.9/lib/python/site-packages/google/oauth2/credentials.py", line 409, in refresh
    ) = reauth.refresh_grant(
  File "/Users/air/Library/Python/3.9/lib/python/site-packages/google/oauth2/reauth.py", line 366, in refresh_grant
    _client._handle_error_response(response_data, retryable_error)
  File "/Users/air/Library/Python/3.9/lib/python/site-packages/google/oauth2/_client.py", line 69, in _handle_error_response
    raise exceptions.RefreshError(
google.auth.exceptions.RefreshError: ('invalid_scope: Bad Request', {'error': 'invalid_scope', 'error_description': 'Bad Request'})
